Workbook

Sheet 1_Inputs
A1: MW PLANNER - RECOMMENDATION ENGINE V2 SIMULATOR
A2: Configure campaign parameters. All selections filter and score inventories automatically.
A4: CAMPAIGN BASICS | D4: AUDIENCE TARGETING
A5: Country * | B5: Malaysia | C5: =IF(B5="Malaysia","MYR","JPY") | D5: Age Group | E5: 25-44
A6: City Filter | B6: All Cities | D6: Gender | E6: All
A7: Start Date * | B7: 2026-02-01 | D7: Income Level | E7: All
A8: End Date * | B8: 2026-02-28 | D8: Interest | E8: All
A9: Budget * | B9: 100000 | C9: =C5 | D9: Behavior | E9: All
A10: Goal Type * | B10: Impressions
A11: Goal Value | B11: 1000000 | D11: CALCULATED VALUES
D12: Campaign Days: | E12: =DATEDIF(B7,B8,"D")+1 | F12: days
A13: VENUE TARGETING | D13: Pricing Model: | E13: =IF(OR(B10="Impressions",B10="Reach",B10="Carbon Emission"),"CPM","CPS")
A14: Venue Type | B14: All Venues | D14: Currency: | E14: =C5
A15: Classification | B15: All
A16: Type | B16: All | D16: BUDGET ALLOCATION (auto by goal)
D17: Classification | E17: Allocation % | F17: Amount | G17: Rationale
D18: Digital | E18: =IF(B10="Impressions",0.60,IF(B10="Reach",0.55,IF(B10="Ad Plays",0.95,IF(B10="SOV",0.95,0.20)))) | F18: =E18*B9 | G18: =IF(B10="Ad Plays","Ad plays require digital screens",IF(B10="SOV","SOV requires slot-based inventory","Balanced for goal type"))
D19: Classic | E19: =IF(B10="Impressions",0.35,IF(B10="Reach",0.40,IF(B10="Ad Plays",0,IF(B10="SOV",0,0.75)))) | F19: =E19*B9 | G19: =IF(OR(B10="Ad Plays",B10="SOV"),"Classic cannot produce plays/slots","Geographic coverage")
D20: Audio | E20: =1-E18-E19 | F20: =E20*B9 | G20: Remaining allocation

Sheet 2_Inventory_Data
A1: ID | B1: Name | C1: Country | D1: City | E1: City Tier | F1: Classification | G1: Type | H1: Format | I1: Venue Type (IAB) | J1: CPM | K1: CPS | L1: Daily Impressions | M1: Daily Reach | N1: Operating Hours | O1: Slots Per Loop | P1: Slot Duration (sec) | Q1: CO2 per Play (kg) | R1: Age 18-24 | S1: Age 25-34 | T1: Age 35-44 | U1: Age 45-54 | V1: Age 55+ | W1: Male % | X1: Female % | Y1: Income Low | Z1: Income Middle | AA1: Income High | AB1: Income Affluent | AC1: Interest Travel | AD1: Interest Fashion | AE1: Interest Tech | AF1: Interest Food | AG1: Behavior Commuters | AH1: Behavior Shoppers | AI1: Behavior Business | AJ1: Behavior Tourists | AK1: Behavior Residents
A2: MY001 | B2: KLCC Suria Digital Screen | C2: Malaysia | D2: Kuala Lumpur | E2: 1 | F2: Digital | G2: Retail | H2: Mall Digital Screen | I2: Retail: Shopping Center | J2: 8 | K2: 3 | L2: 85000 | M2: 42000 | N2: 16 | O2: 6 | P2: 10 | Q2: 0.02 | R2: 0.25 | S2: 0.35 | T2: 0.25 | U2: 0.1 | V2: 0.05 | W2: 0.45 | X2: 0.55 | Y2: 0.15 | Z2: 0.5 | AA2: 0.3 | AB2: 0.05 | AC2: 0.4 | AD2: 0.35 | AE2: 0.2 | AF2: 0.3 | AG2: 0.15 | AH2: 0.6 | AI2: 0.1 | AJ2: 0.25 | AK2: 0.2
A3: MY002 | B3: KLIA Terminal 1 Arrival | C3: Malaysia | D3: KLIA | E3: 1 | F3: Digital | G3: Transit | H3: Airport Digital | I3: Transit: Airport | J3: 12 | K3: 4 | L3: 120000 | M3: 95000 | N3: 20 | O3: 4 | P3: 15 | Q3: 0.03 | R3: 0.2 | S3: 0.3 | T3: 0.3 | U3: 0.15 | V3: 0.05 | W3: 0.55 | X3: 0.45 | Y3: 0.1 | Z3: 0.35 | AA3: 0.45 | AB3: 0.1 | AC3: 0.7 | AD3: 0.2 | AE3: 0.15 | AF3: 0.2 | AG3: 0.05 | AH3: 0.15 | AI3: 0.4 | AJ3: 0.8 | AK3: 0.05
A4: MY003 | B4: Federal Highway Billboard | C4: Malaysia | D4: Petaling Jaya | E4: 2 | F4: Digital | G4: OOH | H4: Digital Billboard | I4: Billboard: Highway | J4: 5 | K4: 2 | L4: 150000 | M4: 120000 | N4: 18 | O4: 4 | P4: 15 | Q4: 0.04 | R4: 0.2 | S4: 0.35 | T4: 0.3 | U4: 0.1 | V4: 0.05 | W4: 0.6 | X4: 0.4 | Y4: 0.2 | Z4: 0.5 | AA4: 0.25 | AB4: 0.05 | AC4: 0.3 | AD4: 0.25 | AE4: 0.25 | AF4: 0.25 | AG4: 0.7 | AH4: 0.1 | AI4: 0.3 | AJ4: 0.05 | AK4: 0.4
A5: MY004 | B5: Pavilion KL Entrance | C5: Malaysia | D5: Kuala Lumpur | E5: 1 | F5: Digital | G5: Retail | H5: Mall Digital Screen | I5: Retail: Shopping Center | J5: 9 | K5: 3 | L5: 95000 | M5: 48000 | N5: 14 | O5: 6 | P5: 10 | Q5: 0.02 | R5: 0.3 | S5: 0.35 | T5: 0.2 | U5: 0.1 | V5: 0.05 | W5: 0.4 | X5: 0.6 | Y5: 0.1 | Z5: 0.4 | AA5: 0.4 | AB5: 0.1 | AC5: 0.35 | AD5: 0.5 | AE5: 0.2 | AF5: 0.35 | AG5: 0.1 | AH5: 0.7 | AI5: 0.15 | AJ5: 0.2 | AK5: 0.15
A6: MY005 | B6: KL Sentral LRT Station | C6: Malaysia | D6: Kuala Lumpur | E6: 1 | F6: Digital | G6: Transit | H6: Station Digital | I6: Transit: Rail/Metro Station | J6: 6 | K6: 2 | L6: 180000 | M6: 85000 | N6: 18 | O6: 6 | P6: 10 | Q6: 0.025 | R6: 0.25 | S6: 0.4 | T6: 0.25 | U6: 0.08 | V6: 0.02 | W6: 0.52 | X6: 0.48 | Y6: 0.25 | Z6: 0.55 | AA6: 0.18 | AB6: 0.02 | AC6: 0.35 | AD6: 0.2 | AE6: 0.3 | AF6: 0.25 | AG6: 0.8 | AH6: 0.05 | AI6: 0.35 | AJ6: 0.1 | AK6: 0.3
A7: MY006 | B7: Menara KEN Office Lobby | C7: Malaysia | D7: Kuala Lumpur | E7: 1 | F7: Digital | G7: Network | H7: Office Lobby Network | I7: Office Building | J7: 5 | K7: 1.5 | L7: 25000 | M7: 8000 | N7: 12 | O7: 4 | P7: 10 | Q7: 0.015 | R7: 0.15 | S7: 0.45 | T7: 0.3 | U7: 0.08 | V7: 0.02 | W7: 0.55 | X7: 0.45 | Y7: 0.05 | Z7: 0.4 | AA7: 0.45 | AB7: 0.1 | AC7: 0.25 | AD7: 0.3 | AE7: 0.5 | AF7: 0.2 | AG7: 0.1 | AH7: 0.05 | AI7: 0.9 | AJ7: 0.02 | AK7: 0.05
A8: MY007 | B8: Bangsar LRT Station | C8: Malaysia | D8: Kuala Lumpur | E8: 1 | F8: Digital | G8: Transit | H8: Station Digital | I8: Transit: Rail/Metro Station | J8: 6 | K8: 2 | L8: 65000 | M8: 32000 | N8: 16 | O8: 6 | P8: 10 | Q8: 0.02 | R8: 0.3 | S8: 0.4 | T8: 0.2 | U8: 0.07 | V8: 0.03 | W8: 0.48 | X8: 0.52 | Y8: 0.15 | Z8: 0.55 | AA8: 0.25 | AB8: 0.05 | AC8: 0.4 | AD8: 0.35 | AE8: 0.25 | AF8: 0.35 | AG8: 0.75 | AH8: 0.15 | AI8: 0.2 | AJ8: 0.08 | AK8: 0.25
A9: MY008 | B9: Jalan Bukit Bintang LED | C9: Malaysia | D9: Kuala Lumpur | E9: 1 | F9: Digital | G9: OOH | H9: LED Screen | I9: Billboard: Roadside | J9: 10 | K9: 3.5 | L9: 200000 | M9: 150000 | N9: 24 | O9: 4 | P9: 15 | Q9: 0.05 | R9: 0.3 | S9: 0.35 | T9: 0.2 | U9: 0.1 | V9: 0.05 | W9: 0.5 | X9: 0.5 | Y9: 0.2 | Z9: 0.45 | AA9: 0.3 | AB9: 0.05 | AC9: 0.45 | AD9: 0.4 | AE9: 0.25 | AF9: 0.4 | AG9: 0.3 | AH9: 0.5 | AI9: 0.15 | AJ9: 0.4 | AK9: 0.15
A10: MY009 | B10: Penang Gurney Plaza | C10: Malaysia | D10: Penang | E10: 2 | F10: Digital | G10: Retail | H10: Mall Digital Screen | I10: Retail: Shopping Center | J10: 7 | K10: 2.5 | L10: 55000 | M10: 28000 | N10: 14 | O10: 6 | P10: 10 | Q10: 0.02 | R10: 0.25 | S10: 0.3 | T10: 0.25 | U10: 0.12 | V10: 0.08 | W10: 0.45 | X10: 0.55 | Y10: 0.2 | Z10: 0.55 | AA10: 0.22 | AB10: 0.03 | AC10: 0.35 | AD10: 0.3 | AE10: 0.2 | AF10: 0.35 | AG10: 0.2 | AH10: 0.65 | AI10: 0.1 | AJ10: 0.15 | AK10: 0.25
A11: MY010 | B11: Johor Bahru City Square | C11: Malaysia | D11: Johor Bahru | E11: 2 | F11: Digital | G11: Retail | H11: Mall Digital Screen | I11: Retail: Shopping Center | J11: 6 | K11: 2 | L11: 45000 | M11: 22000 | N11: 12 | O11: 6 | P11: 10 | Q11: 0.018 | R11: 0.3 | S11: 0.35 | T11: 0.2 | U11: 0.1 | V11: 0.05 | W11: 0.48 | X11: 0.52 | Y11: 0.25 | Z11: 0.55 | AA11: 0.18 | AB11: 0.02 | AC11: 0.3 | AD11: 0.25 | AE11: 0.2 | AF11: 0.3 | AG11: 0.25 | AH11: 0.6 | AI11: 0.1 | AJ11: 0.2 | AK11: 0.3
A12: MY011 | B12: Kota Kinabalu Airport | C12: Malaysia | D12: Kota Kinabalu | E12: 2 | F12: Digital | G12: Transit | H12: Airport Digital | I12: Transit: Airport | J12: 8 | K12: 3 | L12: 35000 | M12: 28000 | N12: 16 | O12: 4 | P12: 15 | Q12: 0.025 | R12: 0.25 | S12: 0.35 | T12: 0.25 | U12: 0.1 | V12: 0.05 | W12: 0.52 | X12: 0.48 | Y12: 0.15 | Z12: 0.45 | AA12: 0.35 | AB12: 0.05 | AC12: 0.6 | AD12: 0.2 | AE12: 0.15 | AF12: 0.25 | AG12: 0.1 | AH12: 0.15 | AI12: 0.35 | AJ12: 0.7 | AK12: 0.1
A13: MY012 | B13: Sprint Highway Billboard | C13: Malaysia | D13: Petaling Jaya | E13: 2 | F13: Classic | G13: OOH | H13: Bulletin | I13: Billboard: Highway | J13: 4 | K13: 0 | L13: 130000 | M13: 105000 | N13: 24 | O13: 0 | P13: 0 | Q13: 0 | R13: 0.2 | S13: 0.35 | T13: 0.3 | U13: 0.1 | V13: 0.05 | W13: 0.6 | X13: 0.4 | Y13: 0.25 | Z13: 0.5 | AA13: 0.22 | AB13: 0.03 | AC13: 0.25 | AD13: 0.2 | AE13: 0.25 | AF13: 0.25 | AG13: 0.7 | AH13: 0.1 | AI13: 0.25 | AJ13: 0.05 | AK13: 0.35
... A41: JP020 | B41: FM Yokohama 84.7 | C41: Japan | D41: Yokohama | E41: 2 | F41: Audio | G41: Radio | H41: AM/FM Radio Spot | I41: Audio: Radio | J41: 5.5 | K41: 2 | L41: 550000 | M41: 280000 | N41: 24 | O41: 0 | P41: 30 | Q41: 0.002 | R41: 0.25 | S41: 0.35 | T41: 0.25 | U41: 0.1 | V41: 0.05 | W41: 0.48 | X41: 0.52 | Y41: 0.18 | Z41: 0.5 | AA41: 0.28 | AB41: 0.04 | AC41: 0.35 | AD41: 0.38 | AE41: 0.3 | AF41: 0.35 | AG41: 0.52 | AH41: 0.28 | AI41: 0.35 | AJ41: 0.18 | AK41: 0.22

Sheet 3_Scoring
A1: INVENTORY SCORING - 8 FACTORS (with filters)
A2: Scores are calculated only for inventories matching Country, City, Venue, and Classification filters. Non-matching rows show 0.
A4: ID | B4: Name | C4: City | D4: Tier | E4: Filter Match | F4: Country | G4: Geo Fit | H4: Availability | I4: Budget Fit | J4: Audience Fit | K4: Brand Fit | L4: Quality | M4: Time Fit | N4: FINAL SCORE | O4: RANK | P4: Digital Rank | Q4: Classic Rank | R4: Audio Rank
A5: ='2_Inventory_Data'!A2 | B5: ='2_Inventory_Data'!B2 | C5: ='2_Inventory_Data'!D2 | D5: ='2_Inventory_Data'!E2 | E5: =IF(AND('2_Inventory_Data'!C2='1_Inputs'!$B$5,OR('1_Inputs'!$B$6="All Cities",'2_Inventory_Data'!D2='1_Inputs'!$B$6),OR('1_Inputs'!$B$14="All Venues",'2_Inventory_Data'!I2='1_Inputs'!$B$14),OR('1_Inputs'!$B$15="All",'2_Inventory_Data'!F2='1_Inputs'!$B$15),OR('1_Inputs'!$B$16="All",'2_Inventory_Data'!G2='1_Inputs'!$B$16)),"MATCH","FILTERED") | F5: =IF(E5="MATCH",100,0) | G5: =IF(E5="MATCH",IF(D5=1,100,IF(D5=2,85,70)),0) | H5: =IF(E5="MATCH",80+MOD(ROW(),21),0) | I5: =IF(E5="MATCH",MAX(0,100-'2_Inventory_Data'!J2*0.3),0) | J5: =IF(E5="FILTERED",0,ROUND((IF('1_Inputs'!$E$5="All Ages",50,IF('1_Inputs'!$E$5="25-44",('2_Inventory_Data'!S2+'2_Inventory_Data'!T2)*100,IF('1_Inputs'!$E$5="18-24",'2_Inventory_Data'!R2*100,IF('1_Inputs'!$E$5="25-34",'2_Inventory_Data'!S2*100,IF('1_Inputs'!$E$5="35-44",'2_Inventory_Data'!T2*100,IF('1_Inputs'!$E$5="45-54",'2_Inventory_Data'!U2*100,IF('1_Inputs'!$E$5="55+",'2_Inventory_Data'!V2*100,50)))))))+IF('1_Inputs'!$E$8="All",50,IF('1_Inputs'!$E$8="Travel",'2_Inventory_Data'!AC2*100,IF('1_Inputs'!$E$8="Fashion",'2_Inventory_Data'!AD2*100,IF('1_Inputs'!$E$8="Technology",'2_Inventory_Data'!AE2*100,IF('1_Inputs'!$E$8="Food & Beverage",'2_Inventory_Data'!AF2*100,50)))))+IF('1_Inputs'!$E$9="All",50,IF('1_Inputs'!$E$9="Commuters",'2_Inventory_Data'!AG2*100,IF('1_Inputs'!$E$9="Shoppers",'2_Inventory_Data'!AH2*100,IF('1_Inputs'!$E$9="Business Travelers",'2_Inventory_Data'!AI2*100,IF('1_Inputs'!$E$9="Tourists",'2_Inventory_Data'!AJ2*100,50))))))/3,1)) | K5: =IF(E5="FILTERED",0,IF(OR('2_Inventory_Data'!I2="Transit: Airport",'2_Inventory_Data'!I2="Transit: Rail/Metro Station"),90,IF('2_Inventory_Data'!I2="Retail: Shopping Center",75,65))) | L5: =IF(E5="FILTERED",0,MIN(100,'2_Inventory_Data'!L2/5000)) | M5: =IF(E5="FILTERED",0,MIN(100,'2_Inventory_Data'!N2*4.5)) | N5: =IF(E5="FILTERED",0,ROUND(G5*0.15+H5*0.10+I5*0.18+J5*0.22+K5*0.10+L5*0.10+M5*0.10+F5*0.05,1)) | O5: =IF(N5=0,"",RANK(N5,$N$5:$N$44,0)) | P5: =IF(OR(E5="FILTERED",'2_Inventory_Data'!F2<>"Digital"),"",COUNTIFS($E$5:$E$44,"MATCH",'2_Inventory_Data'!$F$2:$F$41,"Digital",$N$5:$N$44,">"&N5)+1) | Q5: =IF(OR(E5="FILTERED",'2_Inventory_Data'!F2<>"Classic"),"",COUNTIFS($E$5:$E$44,"MATCH",'2_Inventory_Data'!$F$2:$F$41,"Classic",$N$5:$N$44,">"&N5)+1) | R5: =IF(OR(E5="FILTERED",'2_Inventory_Data'!F2<>"Audio"),"",COUNTIFS($E$5:$E$44,"MATCH",'2_Inventory_Data'!$F$2:$F$41,"Audio",$N$5:$N$44,">"&N5)+1)
A6: ='2_Inventory_Data'!A3 | B6: ='2_Inventory_Data'!B3 | C6: ='2_Inventory_Data'!D3 | D6: ='2_Inventory_Data'!E3 | E6: =IF(AND('2_Inventory_Data'!C3='1_Inputs'!$B$5,OR('1_Inputs'!$B$6="All Cities",'2_Inventory_Data'!D3='1_Inputs'!$B$6),OR('1_Inputs'!$B$14="All Venues",'2_Inventory_Data'!I3='1_Inputs'!$B$14),OR('1_Inputs'!$B$15="All",'2_Inventory_Data'!F3='1_Inputs'!$B$15),OR('1_Inputs'!$B$16="All",'2_Inventory_Data'!G3='1_Inputs'!$B$16)),"MATCH","FILTERED") | F6: =IF(E6="MATCH",100,0) | G6: =IF(E6="MATCH",IF(D6=1,100,IF(D6=2,85,70)),0) | H6: =IF(E6="MATCH",80+MOD(ROW(),21),0) | I6: =IF(E6="MATCH",MAX(0,100-'2_Inventory_Data'!J3*0.3),0) | J6: =IF(E6="FILTERED",0,ROUND((IF('1_Inputs'!$E$5="All Ages",50,IF('1_Inputs'!$E$5="25-44",('2_Inventory_Data'!S3+'2_Inventory_Data'!T3)*100,IF('1_Inputs'!$E$5="18-24",'2_Inventory_Data'!R3*100,IF('1_Inputs'!$E$5="25-34",'2_Inventory_Data'!S3*100,IF('1_Inputs'!$E$5="35-44",'2_Inventory_Data'!T3*100,IF('1_Inputs'!$E$5="45-54",'2_Inventory_Data'!U3*100,IF('1_Inputs'!$E$5="55+",'2_Inventory_Data'!V3*100,50)))))))+IF('1_Inputs'!$E$8="All",50,IF('1_Inputs'!$E$8="Travel",'2_Inventory_Data'!AC3*100,IF('1_Inputs'!$E$8="Fashion",'2_Inventory_Data'!AD3*100,IF('1_Inputs'!$E$8="Technology",'2_Inventory_Data'!AE3*100,IF('1_Inputs'!$E$8="Food & Beverage",'2_Inventory_Data'!AF3*100,50)))))+IF('1_Inputs'!$E$9="All",50,IF('1_Inputs'!$E$9="Commuters",'2_Inventory_Data'!AG3*100,IF('1_Inputs'!$E$9="Shoppers",'2_Inventory_Data'!AH3*100,IF('1_Inputs'!$E$9="Business Travelers",'2_Inventory_Data'!AI3*100,IF('1_Inputs'!$E$9="Tourists",'2_Inventory_Data'!AJ3*100,50))))))/3,1)) | K6: =IF(E6="FILTERED",0,IF(OR('2_Inventory_Data'!I3="Transit: Airport",'2_Inventory_Data'!I3="Transit: Rail/Metro Station"),90,IF('2_Inventory_Data'!I3="Retail: Shopping Center",75,65))) | L6: =IF(E6="FILTERED",0,MIN(100,'2_Inventory_Data'!L3/5000)) | M6: =IF(E6="FILTERED",0,MIN(100,'2_Inventory_Data'!N3*4.5)) | N6: =IF(E6="FILTERED",0,ROUND(G6*0.15+H6*0.10+I6*0.18+J6*0.22+K6*0.10+L6*0.10+M6*0.10+F6*0.05,1)) | O6: =IF(N6=0,"",RANK(N6,$N$5:$N$44,0)) | P6: =IF(OR(E6="FILTERED",'2_Inventory_Data'!F3<>"Digital"),"",COUNTIFS($E$5:$E$44,"MATCH",'2_Inventory_Data'!$F$2:$F$41,"Digital",$N$5:$N$44,">"&N6)+1) | Q6: =IF(OR(E6="FILTERED",'2_Inventory_Data'!F3<>"Classic"),"",COUNTIFS($E$5:$E$44,"MATCH",'2_Inventory_Data'!$F$2:$F$41,"Classic",$N$5:$N$44,">"&N6)+1) | R6: =IF(OR(E6="FILTERED",'2_Inventory_Data'!F3<>"Audio"),"",COUNTIFS($E$5:$E$44,"MATCH",'2_Inventory_Data'!$F$2:$F$41,"Audio",$N$5:$N$44,">"&N6)+1)
A7: ='2_Inventory_Data'!A4 | B7: ='2_Inventory_Data'!B4 | C7: ='2_Inventory_Data'!D4 | D7: ='2_Inventory_Data'!E4 | E7: =IF(AND('2_Inventory_Data'!C4='1_Inputs'!$B$5,OR('1_Inputs'!$B$6="All Cities",'2_Inventory_Data'!D4='1_Inputs'!$B$6),OR('1_Inputs'!$B$14="All Venues",'2_Inventory_Data'!I4='1_Inputs'!$B$14),OR('1_Inputs'!$B$15="All",'2_Inventory_Data'!F4='1_Inputs'!$B$15),OR('1_Inputs'!$B$16="All",'2_Inventory_Data'!G4='1_Inputs'!$B$16)),"MATCH","FILTERED") | F7: =IF(E7="MATCH",100,0) | G7: =IF(E7="MATCH",IF(D7=1,100,IF(D7=2,85,70)),0) | H7: =IF(E7="MATCH",80+MOD(ROW(),21),0) | I7: =IF(E7="MATCH",MAX(0,100-'2_Inventory_Data'!J4*0.3),0) | J7: =IF(E7="FILTERED",0,ROUND((IF('1_Inputs'!$E$5="All Ages",50,IF('1_Inputs'!$E$5="25-44",('2_Inventory_Data'!S4+'2_Inventory_Data'!T4)*100,IF('1_Inputs'!$E$5="18-24",'2_Inventory_Data'!R4*100,IF('1_Inputs'!$E$5="25-34",'2_Inventory_Data'!S4*100,IF('1_Inputs'!$E$5="35-44",'2_Inventory_Data'!T4*100,IF('1_Inputs'!$E$5="45-54",'2_Inventory_Data'!U4*100,IF('1_Inputs'!$E$5="55+",'2_Inventory_Data'!V4*100,50)))))))+IF('1_Inputs'!$E$8="All",50,IF('1_Inputs'!$E$8="Travel",'2_Inventory_Data'!AC4*100,IF('1_Inputs'!$E$8="Fashion",'2_Inventory_Data'!AD4*100,IF('1_Inputs'!$E$8="Technology",'2_Inventory_Data'!AE4*100,IF('1_Inputs'!$E$8="Food & Beverage",'2_Inventory_Data'!AF4*100,50)))))+IF('1_Inputs'!$E$9="All",50,IF('1_Inputs'!$E$9="Commuters",'2_Inventory_Data'!AG4*100,IF('1_Inputs'!$E$9="Shoppers",'2_Inventory_Data'!AH4*100,IF('1_Inputs'!$E$9="Business Travelers",'2_Inventory_Data'!AI4*100,IF('1_Inputs'!$E$9="Tourists",'2_Inventory_Data'!AJ4*100,50))))))/3,1)) | K7: =IF(E7="FILTERED",0,IF(OR('2_Inventory_Data'!I4="Transit: Airport",'2_Inventory_Data'!I4="Transit: Rail/Metro Station"),90,IF('2_Inventory_Data'!I4="Retail: Shopping Center",75,65))) | L7: =IF(E7="FILTERED",0,MIN(100,'2_Inventory_Data'!L4/5000)) | M7: =IF(E7="FILTERED",0,MIN(100,'2_Inventory_Data'!N4*4.5)) | N7: =IF(E7="FILTERED",0,ROUND(G7*0.15+H7*0.10+I7*0.18+J7*0.22+K7*0.10+L7*0.10+M7*0.10+F7*0.05,1)) | O7: =IF(N7=0,"",RANK(N7,$N$5:$N$44,0)) | P7: =IF(OR(E7="FILTERED",'2_Inventory_Data'!F4<>"Digital"),"",COUNTIFS($E$5:$E$44,"MATCH",'2_Inventory_Data'!$F$2:$F$41,"Digital",$N$5:$N$44,">"&N7)+1) | Q7: =IF(OR(E7="FILTERED",'2_Inventory_Data'!F4<>"Classic"),"",COUNTIFS($E$5:$E$44,"MATCH",'2_Inventory_Data'!$F$2:$F$41,"Classic",$N$5:$N$44,">"&N7)+1) | R7: =IF(OR(E7="FILTERED",'2_Inventory_Data'!F4<>"Audio"),"",COUNTIFS($E$5:$E$44,"MATCH",'2_Inventory_Data'!$F$2:$F$41,"Audio",$N$5:$N$44,">"&N7)+1)
A8: ='2_Inventory_Data'!A5 | B8: ='2_Inventory_Data'!B5 | C8: ='2_Inventory_Data'!D5 | D8: ='2_Inventory_Data'!E5 | E8: =IF(AND('2_Inventory_Data'!C5='1_Inputs'!$B$5,OR('1_Inputs'!$B$6="All Cities",'2_Inventory_Data'!D5='1_Inputs'!$B$6),OR('1_Inputs'!$B$14="All Venues",'2_Inventory_Data'!I5='1_Inputs'!$B$14),OR('1_Inputs'!$B$15="All",'2_Inventory_Data'!F5='1_Inputs'!$B$15),OR('1_Inputs'!$B$16="All",'2_Inventory_Data'!G5='1_Inputs'!$B$16)),"MATCH","FILTERED") | F8: =IF(E8="MATCH",100,0) | G8: =IF(E8="MATCH",IF(D8=1,100,IF(D8=2,85,70)),0) | H8: =IF(E8="MATCH",80+MOD(ROW(),21),0) | I8: =IF(E8="MATCH",MAX(0,100-'2_Inventory_Data'!J5*0.3),0) | J8: =IF(E8="FILTERED",0,ROUND((IF('1_Inputs'!$E$5="All Ages",50,IF('1_Inputs'!$E$5="25-44",('2_Inventory_Data'!S5+'2_Inventory_Data'!T5)*100,IF('1_Inputs'!$E$5="18-24",'2_Inventory_Data'!R5*100,IF('1_Inputs'!$E$5="25-34",'2_Inventory_Data'!S5*100,IF('1_Inputs'!$E$5="35-44",'2_Inventory_Data'!T5*100,IF('1_Inputs'!$E$5="45-54",'2_Inventory_Data'!U5*100,IF('1_Inputs'!$E$5="55+",'2_Inventory_Data'!V5*100,50)))))))+IF('1_Inputs'!$E$8="All",50,IF('1_Inputs'!$E$8="Travel",'2_Inventory_Data'!AC5*100,IF('1_Inputs'!$E$8="Fashion",'2_Inventory_Data'!AD5*100,IF('1_Inputs'!$E$8="Technology",'2_Inventory_Data'!AE5*100,IF('1_Inputs'!$E$8="Food & Beverage",'2_Inventory_Data'!AF5*100,50)))))+IF('1_Inputs'!$E$9="All",50,IF('1_Inputs'!$E$9="Commuters",'2_Inventory_Data'!AG5*100,IF('1_Inputs'!$E$9="Shoppers",'2_Inventory_Data'!AH5*100,IF('1_Inputs'!$E$9="Business Travelers",'2_Inventory_Data'!AI5*100,IF('1_Inputs'!$E$9="Tourists",'2_Inventory_Data'!AJ5*100,50))))))/3,1)) | K8: =IF(E8="FILTERED",0,IF(OR('2_Inventory_Data'!I5="Transit: Airport",'2_Inventory_Data'!I5="Transit: Rail/Metro Station"),90,IF('2_Inventory_Data'!I5="Retail: Shopping Center",75,65))) | L8: =IF(E8="FILTERED",0,MIN(100,'2_Inventory_Data'!L5/5000)) | M8: =IF(E8="FILTERED",0,MIN(100,'2_Inventory_Data'!N5*4.5)) | N8: =IF(E8="FILTERED",0,ROUND(G8*0.15+H8*0.10+I8*0.18+J8*0.22+K8*0.10+L8*0.10+M8*0.10+F8*0.05,1)) | O8: =IF(N8=0,"",RANK(N8,$N$5:$N$44,0)) | P8: =IF(OR(E8="FILTERED",'2_Inventory_Data'!F5<>"Digital"),"",COUNTIFS($E$5:$E$44,"MATCH",'2_Inventory_Data'!$F$2:$F$41,"Digital",$N$5:$N$44,">"&N8)+1) | Q8: =IF(OR(E8="FILTERED",'2_Inventory_Data'!F5<>"Classic"),"",COUNTIFS($E$5:$E$44,"MATCH",'2_Inventory_Data'!$F$2:$F$41,"Classic",$N$5:$N$44,">"&N8)+1) | R8: =IF(OR(E8="FILTERED",'2_Inventory_Data'!F5<>"Audio"),"",COUNTIFS($E$5:$E$44,"MATCH",'2_Inventory_Data'!$F$2:$F$41,"Audio",$N$5:$N$44,">"&N8)+1)
A9: ='2_Inventory_Data'!A6 | B9: ='2_Inventory_Data'!B6 | C9: ='2_Inventory_Data'!D6 | D9: ='2_Inventory_Data'!E6 | E9: =IF(AND('2_Inventory_Data'!C6='1_Inputs'!$B$5,OR('1_Inputs'!$B$6="All Cities",'2_Inventory_Data'!D6='1_Inputs'!$B$6),OR('1_Inputs'!$B$14="All Venues",'2_Inventory_Data'!I6='1_Inputs'!$B$14),OR('1_Inputs'!$B$15="All",'2_Inventory_Data'!F6='1_Inputs'!$B$15),OR('1_Inputs'!$B$16="All",'2_Inventory_Data'!G6='1_Inputs'!$B$16)),"MATCH","FILTERED") | F9: =IF(E9="MATCH",100,0) | G9: =IF(E9="MATCH",IF(D9=1,100,IF(D9=2,85,70)),0) | H9: =IF(E9="MATCH",80+MOD(ROW(),21),0) | I9: =IF(E9="MATCH",MAX(0,100-'2_Inventory_Data'!J6*0.3),0) | J9: =IF(E9="FILTERED",0,ROUND((IF('1_Inputs'!$E$5="All Ages",50,IF('1_Inputs'!$E$5="25-44",('2_Inventory_Data'!S6+'2_Inventory_Data'!T6)*100,IF('1_Inputs'!$E$5="18-24",'2_Inventory_Data'!R6*100,IF('1_Inputs'!$E$5="25-34",'2_Inventory_Data'!S6*100,IF('1_Inputs'!$E$5="35-44",'2_Inventory_Data'!T6*100,IF('1_Inputs'!$E$5="45-54",'2_Inventory_Data'!U6*100,IF('1_Inputs'!$E$5="55+",'2_Inventory_Data'!V6*100,50)))))))+IF('1_Inputs'!$E$8="All",50,IF('1_Inputs'!$E$8="Travel",'2_Inventory_Data'!AC6*100,IF('1_Inputs'!$E$8="Fashion",'2_Inventory_Data'!AD6*100,IF('1_Inputs'!$E$8="Technology",'2_Inventory_Data'!AE6*100,IF('1_Inputs'!$E$8="Food & Beverage",'2_Inventory_Data'!AF6*100,50)))))+IF('1_Inputs'!$E$9="All",50,IF('1_Inputs'!$E$9="Commuters",'2_Inventory_Data'!AG6*100,IF('1_Inputs'!$E$9="Shoppers",'2_Inventory_Data'!AH6*100,IF('1_Inputs'!$E$9="Business Travelers",'2_Inventory_Data'!AI6*100,IF('1_Inputs'!$E$9="Tourists",'2_Inventory_Data'!AJ6*100,50))))))/3,1)) | K9: =IF(E9="FILTERED",0,IF(OR('2_Inventory_Data'!I6="Transit: Airport",'2_Inventory_Data'!I6="Transit: Rail/Metro Station"),90,IF('2_Inventory_Data'!I6="Retail: Shopping Center",75,65))) | L9: =IF(E9="FILTERED",0,MIN(100,'2_Inventory_Data'!L6/5000)) | M9: =IF(E9="FILTERED",0,MIN(100,'2_Inventory_Data'!N6*4.5)) | N9: =IF(E9="FILTERED",0,ROUND(G9*0.15+H9*0.10+I9*0.18+J9*0.22+K9*0.10+L9*0.10+M9*0.10+F9*0.05,1)) | O9: =IF(N9=0,"",RANK(N9,$N$5:$N$44,0)) | P9: =IF(OR(E9="FILTERED",'2_Inventory_Data'!F6<>"Digital"),"",COUNTIFS($E$5:$E$44,"MATCH",'2_Inventory_Data'!$F$2:$F$41,"Digital",$N$5:$N$44,">"&N9)+1) | Q9: =IF(OR(E9="FILTERED",'2_Inventory_Data'!F6<>"Classic"),"",COUNTIFS($E$5:$E$44,"MATCH",'2_Inventory_Data'!$F$2:$F$41,"Classic",$N$5:$N$44,">"&N9)+1) | R9: =IF(OR(E9="FILTERED",'2_Inventory_Data'!F6<>"Audio"),"",COUNTIFS($E$5:$E$44,"MATCH",'2_Inventory_Data'!$F$2:$F$41,"Audio",$N$5:$N$44,">"&N9)+1)
A10: ='2_Inventory_Data'!A7 | B10: ='2_Inventory_Data'!B7 | C10: ='2_Inventory_Data'!D7 | D10: ='2_Inventory_Data'!E7 | E10: =IF(AND('2_Inventory_Data'!C7='1_Inputs'!$B$5,OR('1_Inputs'!$B$6="All Cities",'2_Inventory_Data'!D7='1_Inputs'!$B$6),OR('1_Inputs'!$B$14="All Venues",'2_Inventory_Data'!I7='1_Inputs'!$B$14),OR('1_Inputs'!$B$15="All",'2_Inventory_Data'!F7='1_Inputs'!$B$15),OR('1_Inputs'!$B$16="All",'2_Inventory_Data'!G7='1_Inputs'!$B$16)),"MATCH","FILTERED") | F10: =IF(E10="MATCH",100,0) | G10: =IF(E10="MATCH",IF(D10=1,100,IF(D10=2,85,70)),0) | H10: =IF(E10="MATCH",80+MOD(ROW(),21),0) | I10: =IF(E10="MATCH",MAX(0,100-'2_Inventory_Data'!J7*0.3),0) | J10: =IF(E10="FILTERED",0,ROUND((IF('1_Inputs'!$E$5="All Ages",50,IF('1_Inputs'!$E$5="25-44",('2_Inventory_Data'!S7+'2_Inventory_Data'!T7)*100,IF('1_Inputs'!$E$5="18-24",'2_Inventory_Data'!R7*100,IF('1_Inputs'!$E$5="25-34",'2_Inventory_Data'!S7*100,IF('1_Inputs'!$E$5="35-44",'2_Inventory_Data'!T7*100,IF('1_Inputs'!$E$5="45-54",'2_Inventory_Data'!U7*100,IF('1_Inputs'!$E$5="55+",'2_Inventory_Data'!V7*100,50)))))))+IF('1_Inputs'!$E$8="All",50,IF('1_Inputs'!$E$8="Travel",'2_Inventory_Data'!AC7*100,IF('1_Inputs'!$E$8="Fashion",'2_Inventory_Data'!AD7*100,IF('1_Inputs'!$E$8="Technology",'2_Inventory_Data'!AE7*100,IF('1_Inputs'!$E$8="Food & Beverage",'2_Inventory_Data'!AF7*100,50)))))+IF('1_Inputs'!$E$9="All",50,IF('1_Inputs'!$E$9="Commuters",'2_Inventory_Data'!AG7*100,IF('1_Inputs'!$E$9="Shoppers",'2_Inventory_Data'!AH7*100,IF('1_Inputs'!$E$9="Business Travelers",'2_Inventory_Data'!AI7*100,IF('1_Inputs'!$E$9="Tourists",'2_Inventory_Data'!AJ7*100,50))))))/3,1)) | K10: =IF(E10="FILTERED",0,IF(OR('2_Inventory_Data'!I7="Transit: Airport",'2_Inventory_Data'!I7="Transit: Rail/Metro Station"),90,IF('2_Inventory_Data'!I7="Retail: Shopping Center",75,65))) | L10: =IF(E10="FILTERED",0,MIN(100,'2_Inventory_Data'!L7/5000)) | M10: =IF(E10="FILTERED",0,MIN(100,'2_Inventory_Data'!N7*4.5)) | N10: =IF(E10="FILTERED",0,ROUND(G10*0.15+H10*0.10+I10*0.18+J10*0.22+K10*0.10+L10*0.10+M10*0.10+F10*0.05,1)) | O10: =IF(N10=0,"",RANK(N10,$N$5:$N$44,0)) | P10: =IF(OR(E10="FILTERED",'2_Inventory_Data'!F7<>"Digital"),"",COUNTIFS($E$5:$E$44,"MATCH",'2_Inventory_Data'!$F$2:$F$41,"Digital",$N$5:$N$44,">"&N10)+1) | Q10: =IF(OR(E10="FILTERED",'2_Inventory_Data'!F7<>"Classic"),"",COUNTIFS($E$5:$E$44,"MATCH",'2_Inventory_Data'!$F$2:$F$41,"Classic",$N$5:$N$44,">"&N10)+1) | R10: =IF(OR(E10="FILTERED",'2_Inventory_Data'!F7<>"Audio"),"",COUNTIFS($E$5:$E$44,"MATCH",'2_Inventory_Data'!$F$2:$F$41,"Audio",$N$5:$N$44,">"&N10)+1)
A11: ='2_Inventory_Data'!A8 | B11: ='2_Inventory_Data'!B8 | C11: ='2_Inventory_Data'!D8 | D11: ='2_Inventory_Data'!E8 | E11: =IF(AND('2_Inventory_Data'!C8='1_Inputs'!$B$5,OR('1_Inputs'!$B$6="All Cities",'2_Inventory_Data'!D8='1_Inputs'!$B$6),OR('1_Inputs'!$B$14="All Venues",'2_Inventory_Data'!I8='1_Inputs'!$B$14),OR('1_Inputs'!$B$15="All",'2_Inventory_Data'!F8='1_Inputs'!$B$15),OR('1_Inputs'!$B$16="All",'2_Inventory_Data'!G8='1_Inputs'!$B$16)),"MATCH","FILTERED") | F11: =IF(E11="MATCH",100,0) | G11: =IF(E11="MATCH",IF(D11=1,100,IF(D11=2,85,70)),0) | H11: =IF(E11="MATCH",80+MOD(ROW(),21),0) | I11: =IF(E11="MATCH",MAX(0,100-'2_Inventory_Data'!J8*0.3),0) | J11: =IF(E11="FILTERED",0,ROUND((IF('1_Inputs'!$E$5="All Ages",50,IF('1_Inputs'!$E$5="25-44",('2_Inventory_Data'!S8+'2_Inventory_Data'!T8)*100,IF('1_Inputs'!$E$5="18-24",'2_Inventory_Data'!R8*100,IF('1_Inputs'!$E$5="25-34",'2_Inventory_Data'!S8*100,IF('1_Inputs'!$E$5="35-44",'2_Inventory_Data'!T8*100,IF('1_Inputs'!$E$5="45-54",'2_Inventory_Data'!U8*100,IF('1_Inputs'!$E$5="55+",'2_Inventory_Data'!V8*100,50)))))))+IF('1_Inputs'!$E$8="All",50,IF('1_Inputs'!$E$8="Travel",'2_Inventory_Data'!AC8*100,IF('1_Inputs'!$E$8="Fashion",'2_Inventory_Data'!AD8*100,IF('1_Inputs'!$E$8="Technology",'2_Inventory_Data'!AE8*100,IF('1_Inputs'!$E$8="Food & Beverage",'2_Inventory_Data'!AF8*100,50)))))+IF('1_Inputs'!$E$9="All",50,IF('1_Inputs'!$E$9="Commuters",'2_Inventory_Data'!AG8*100,IF('1_Inputs'!$E$9="Shoppers",'2_Inventory_Data'!AH8*100,IF('1_Inputs'!$E$9="Business Travelers",'2_Inventory_Data'!AI8*100,IF('1_Inputs'!$E$9="Tourists",'2_Inventory_Data'!AJ8*100,50))))))/3,1)) | K11: =IF(E11="FILTERED",0,IF(OR('2_Inventory_Data'!I8="Transit: Airport",'2_Inventory_Data'!I8="Transit: Rail/Metro Station"),90,IF('2_Inventory_Data'!I8="Retail: Shopping Center",75,65))) | L11: =IF(E11="FILTERED",0,MIN(100,'2_Inventory_Data'!L8/5000)) | M11: =IF(E11="FILTERED",0,MIN(100,'2_Inventory_Data'!N8*4.5)) | N11: =IF(E11="FILTERED",0,ROUND(G11*0.15+H11*0.10+I11*0.18+J11*0.22+K11*0.10+L11*0.10+M11*0.10+F11*0.05,1)) | O11: =IF(N11=0,"",RANK(N11,$N$5:$N$44,0)) | P11: =IF(OR(E11="FILTERED",'2_Inventory_Data'!F8<>"Digital"),"",COUNTIFS($E$5:$E$44,"MATCH",'2_Inventory_Data'!$F$2:$F$41,"Digital",$N$5:$N$44,">"&N11)+1) | Q11: =IF(OR(E11="FILTERED",'2_Inventory_Data'!F8<>"Classic"),"",COUNTIFS($E$5:$E$44,"MATCH",'2_Inventory_Data'!$F$2:$F$41,"Classic",$N$5:$N$44,">"&N11)+1) | R11: =IF(OR(E11="FILTERED",'2_Inventory_Data'!F8<>"Audio"),"",COUNTIFS($E$5:$E$44,"MATCH",'2_Inventory_Data'!$F$2:$F$41,"Audio",$N$5:$N$44,">"&N11)+1)
A12: ='2_Inventory_Data'!A9 | B12: ='2_Inventory_Data'!B9 | C12: ='2_Inventory_Data'!D9 | D12: ='2_Inventory_Data'!E9 | E12: =IF(AND('2_Inventory_Data'!C9='1_Inputs'!$B$5,OR('1_Inputs'!$B$6="All Cities",'2_Inventory_Data'!D9='1_Inputs'!$B$6),OR('1_Inputs'!$B$14="All Venues",'2_Inventory_Data'!I9='1_Inputs'!$B$14),OR('1_Inputs'!$B$15="All",'2_Inventory_Data'!F9='1_Inputs'!$B$15),OR('1_Inputs'!$B$16="All",'2_Inventory_Data'!G9='1_Inputs'!$B$16)),"MATCH","FILTERED") | F12: =IF(E12="MATCH",100,0) | G12: =IF(E12="MATCH",IF(D12=1,100,IF(D12=2,85,70)),0) | H12: =IF(E12="MATCH",80+MOD(ROW(),21),0) | I12: =IF(E12="MATCH",MAX(0,100-'2_Inventory_Data'!J9*0.3),0) | J12: =IF(E12="FILTERED",0,ROUND((IF('1_Inputs'!$E$5="All Ages",50,IF('1_Inputs'!$E$5="25-44",('2_Inventory_Data'!S9+'2_Inventory_Data'!T9)*100,IF('1_Inputs'!$E$5="18-24",'2_Inventory_Data'!R9*100,IF('1_Inputs'!$E$5="25-34",'2_Inventory_Data'!S9*100,IF('1_Inputs'!$E$5="35-44",'2_Inventory_Data'!T9*100,IF('1_Inputs'!$E$5="45-54",'2_Inventory_Data'!U9*100,IF('1_Inputs'!$E$5="55+",'2_Inventory_Data'!V9*100,50)))))))+IF('1_Inputs'!$E$8="All",50,IF('1_Inputs'!$E$8="Travel",'2_Inventory_Data'!AC9*100,IF('1_Inputs'!$E$8="Fashion",'2_Inventory_Data'!AD9*100,IF('1_Inputs'!$E$8="Technology",'2_Inventory_Data'!AE9*100,IF('1_Inputs'!$E$8="Food & Beverage",'2_Inventory_Data'!AF9*100,50)))))+IF('1_Inputs'!$E$9="All",50,IF('1_Inputs'!$E$9="Commuters",'2_Inventory_Data'!AG9*100,IF('1_Inputs'!$E$9="Shoppers",'2_Inventory_Data'!AH9*100,IF('1_Inputs'!$E$9="Business Travelers",'2_Inventory_Data'!AI9*100,IF('1_Inputs'!$E$9="Tourists",'2_Inventory_Data'!AJ9*100,50))))))/3,1)) | K12: =IF(E12="FILTERED",0,IF(OR('2_Inventory_Data'!I9="Transit: Airport",'2_Inventory_Data'!I9="Transit: Rail/Metro Station"),90,IF('2_Inventory_Data'!I9="Retail: Shopping Center",75,65))) | L12: =IF(E12="FILTERED",0,MIN(100,'2_Inventory_Data'!L9/5000)) | M12: =IF(E12="FILTERED",0,MIN(100,'2_Inventory_Data'!N9*4.5)) | N12: =IF(E12="FILTERED",0,ROUND(G12*0.15+H12*0.10+I12*0.18+J12*0.22+K12*0.10+L12*0.10+M12*0.10+F12*0.05,1)) | O12: =IF(N12=0,"",RANK(N12,$N$5:$N$44,0)) | P12: =IF(OR(E12="FILTERED",'2_Inventory_Data'!F9<>"Digital"),"",COUNTIFS($E$5:$E$44,"MATCH",'2_Inventory_Data'!$F$2:$F$41,"Digital",$N$5:$N$44,">"&N12)+1) | Q12: =IF(OR(E12="FILTERED",'2_Inventory_Data'!F9<>"Classic"),"",COUNTIFS($E$5:$E$44,"MATCH",'2_Inventory_Data'!$F$2:$F$41,"Classic",$N$5:$N$44,">"&N12)+1) | R12: =IF(OR(E12="FILTERED",'2_Inventory_Data'!F9<>"Audio"),"",COUNTIFS($E$5:$E$44,"MATCH",'2_Inventory_Data'!$F$2:$F$41,"Audio",$N$5:$N$44,">"&N12)+1)
A13: ='2_Inventory_Data'!A10 | B13: ='2_Inventory_Data'!B10 | C13: ='2_Inventory_Data'!D10 | D13: ='2_Inventory_Data'!E10 | E13: =IF(AND('2_Inventory_Data'!C10='1_Inputs'!$B$5,OR('1_Inputs'!$B$6="All Cities",'2_Inventory_Data'!D10='1_Inputs'!$B$6),OR('1_Inputs'!$B$14="All Venues",'2_Inventory_Data'!I10='1_Inputs'!$B$14),OR('1_Inputs'!$B$15="All",'2_Inventory_Data'!F10='1_Inputs'!$B$15),OR('1_Inputs'!$B$16="All",'2_Inventory_Data'!G10='1_Inputs'!$B$16)),"MATCH","FILTERED") | F13: =IF(E13="MATCH",100,0) | G13: =IF(E13="MATCH",IF(D13=1,100,IF(D13=2,85,70)),0) | H13: =IF(E13="MATCH",80+MOD(ROW(),21),0) | I13: =IF(E13="MATCH",MAX(0,100-'2_Inventory_Data'!J10*0.3),0) | J13: =IF(E13="FILTERED",0,ROUND((IF('1_Inputs'!$E$5="All Ages",50,IF('1_Inputs'!$E$5="25-44",('2_Inventory_Data'!S10+'2_Inventory_Data'!T10)*100,IF('1_Inputs'!$E$5="18-24",'2_Inventory_Data'!R10*100,IF('1_Inputs'!$E$5="25-34",'2_Inventory_Data'!S10*100,IF('1_Inputs'!$E$5="35-44",'2_Inventory_Data'!T10*100,IF('1_Inputs'!$E$5="45-54",'2_Inventory_Data'!U10*100,IF('1_Inputs'!$E$5="55+",'2_Inventory_Data'!V10*100,50)))))))+IF('1_Inputs'!$E$8="All",50,IF('1_Inputs'!$E$8="Travel",'2_Inventory_Data'!AC10*100,IF('1_Inputs'!$E$8="Fashion",'2_Inventory_Data'!AD10*100,IF('1_Inputs'!$E$8="Technology",'2_Inventory_Data'!AE10*100,IF('1_Inputs'!$E$8="Food & Beverage",'2_Inventory_Data'!AF10*100,50)))))+IF('1_Inputs'!$E$9="All",50,IF('1_Inputs'!$E$9="Commuters",'2_Inventory_Data'!AG10*100,IF('1_Inputs'!$E$9="Shoppers",'2_Inventory_Data'!AH10*100,IF('1_Inputs'!$E$9="Business Travelers",'2_Inventory_Data'!AI10*100,IF('1_Inputs'!$E$9="Tourists",'2_Inventory_Data'!AJ10*100,50))))))/3,1)) | K13: =IF(E13="FILTERED",0,IF(OR('2_Inventory_Data'!I10="Transit: Airport",'2_Inventory_Data'!I10="Transit: Rail/Metro Station"),90,IF('2_Inventory_Data'!I10="Retail: Shopping Center",75,65))) | L13: =IF(E13="FILTERED",0,MIN(100,'2_Inventory_Data'!L10/5000)) | M13: =IF(E13="FILTERED",0,MIN(100,'2_Inventory_Data'!N10*4.5)) | N13: =IF(E13="FILTERED",0,ROUND(G13*0.15+H13*0.10+I13*0.18+J13*0.22+K13*0.10+L13*0.10+M13*0.10+F13*0.05,1)) | O13: =IF(N13=0,"",RANK(N13,$N$5:$N$44,0)) | P13: =IF(OR(E13="FILTERED",'2_Inventory_Data'!F10<>"Digital"),"",COUNTIFS($E$5:$E$44,"MATCH",'2_Inventory_Data'!$F$2:$F$41,"Digital",$N$5:$N$44,">"&N13)+1) | Q13: =IF(OR(E13="FILTERED",'2_Inventory_Data'!F10<>"Classic"),"",COUNTIFS($E$5:$E$44,"MATCH",'2_Inventory_Data'!$F$2:$F$41,"Classic",$N$5:$N$44,">"&N13)+1) | R13: =IF(OR(E13="FILTERED",'2_Inventory_Data'!F10<>"Audio"),"",COUNTIFS($E$5:$E$44,"MATCH",'2_Inventory_Data'!$F$2:$F$41,"Audio",$N$5:$N$44,">"&N13)+1)
A14: ='2_Inventory_Data'!A11 | B14: ='2_Inventory_Data'!B11 | C14: ='2_Inventory_Data'!D11 | D14: ='2_Inventory_Data'!E11 | E14: =IF(AND('2_Inventory_Data'!C11='1_Inputs'!$B$5,OR('1_Inputs'!$B$6="All Cities",'2_Inventory_Data'!D11='1_Inputs'!$B$6),OR('1_Inputs'!$B$14="All Venues",'2_Inventory_Data'!I11='1_Inputs'!$B$14),OR('1_Inputs'!$B$15="All",'2_Inventory_Data'!F11='1_Inputs'!$B$15),OR('1_Inputs'!$B$16="All",'2_Inventory_Data'!G11='1_Inputs'!$B$16)),"MATCH","FILTERED") | F14: =IF(E14="MATCH",100,0) | G14: =IF(E14="MATCH",IF(D14=1,100,IF(D14=2,85,70)),0) | H14: =IF(E14="MATCH",80+MOD(ROW(),21),0) | I14: =IF(E14="MATCH",MAX(0,100-'2_Inventory_Data'!J11*0.3),0) | J14: =IF(E14="FILTERED",0,ROUND((IF('1_Inputs'!$E$5="All Ages",50,IF('1_Inputs'!$E$5="25-44",('2_Inventory_Data'!S11+'2_Inventory_Data'!T11)*100,IF('1_Inputs'!$E$5="18-24",'2_Inventory_Data'!R11*100,IF('1_Inputs'!$E$5="25-34",'2_Inventory_Data'!S11*100,IF('1_Inputs'!$E$5="35-44",'2_Inventory_Data'!T11*100,IF('1_Inputs'!$E$5="45-54",'2_Inventory_Data'!U11*100,IF('1_Inputs'!$E$5="55+",'2_Inventory_Data'!V11*100,50)))))))+IF('1_Inputs'!$E$8="All",50,IF('1_Inputs'!$E$8="Travel",'2_Inventory_Data'!AC11*100,IF('1_Inputs'!$E$8="Fashion",'2_Inventory_Data'!AD11*100,IF('1_Inputs'!$E$8="Technology",'2_Inventory_Data'!AE11*100,IF('1_Inputs'!$E$8="Food & Beverage",'2_Inventory_Data'!AF11*100,50)))))+IF('1_Inputs'!$E$9="All",50,IF('1_Inputs'!$E$9="Commuters",'2_Inventory_Data'!AG11*100,IF('1_Inputs'!$E$9="Shoppers",'2_Inventory_Data'!AH11*100,IF('1_Inputs'!$E$9="Business Travelers",'2_Inventory_Data'!AI11*100,IF('1_Inputs'!$E$9="Tourists",'2_Inventory_Data'!AJ11*100,50))))))/3,1)) | K14: =IF(E14="FILTERED",0,IF(OR('2_Inventory_Data'!I11="Transit: Airport",'2_Inventory_Data'!I11="Transit: Rail/Metro Station"),90,IF('2_Inventory_Data'!I11="Retail: Shopping Center",75,65))) | L14: =IF(E14="FILTERED",0,MIN(100,'2_Inventory_Data'!L11/5000)) | M14: =IF(E14="FILTERED",0,MIN(100,'2_Inventory_Data'!N11*4.5)) | N14: =IF(E14="FILTERED",0,ROUND(G14*0.15+H14*0.10+I14*0.18+J14*0.22+K14*0.10+L14*0.10+M14*0.10+F14*0.05,1)) | O14: =IF(N14=0,"",RANK(N14,$N$5:$N$44,0)) | P14: =IF(OR(E14="FILTERED",'2_Inventory_Data'!F11<>"Digital"),"",COUNTIFS($E$5:$E$44,"MATCH",'2_Inventory_Data'!$F$2:$F$41,"Digital",$N$5:$N$44,">"&N14)+1) | Q14: =IF(OR(E14="FILTERED",'2_Inventory_Data'!F11<>"Classic"),"",COUNTIFS($E$5:$E$44,"MATCH",'2_Inventory_Data'!$F$2:$F$41,"Classic",$N$5:$N$44,">"&N14)+1) | R14: =IF(OR(E14="FILTERED",'2_Inventory_Data'!F11<>"Audio"),"",COUNTIFS($E$5:$E$44,"MATCH",'2_Inventory_Data'!$F$2:$F$41,"Audio",$N$5:$N$44,">"&N14)+1)
A15: ='2_Inventory_Data'!A12 | B15: ='2_Inventory_Data'!B12 | C15: ='2_Inventory_Data'!D12 | D15: ='2_Inventory_Data'!E12 | E15: =IF(AND('2_Inventory_Data'!C12='1_Inputs'!$B$5,OR('1_Inputs'!$B$6="All Cities",'2_Inventory_Data'!D12='1_Inputs'!$B$6),OR('1_Inputs'!$B$14="All Venues",'2_Inventory_Data'!I12='1_Inputs'!$B$14),OR('1_Inputs'!$B$15="All",'2_Inventory_Data'!F12='1_Inputs'!$B$15),OR('1_Inputs'!$B$16="All",'2_Inventory_Data'!G12='1_Inputs'!$B$16)),"MATCH","FILTERED") | F15: =IF(E15="MATCH",100,0) | G15: =IF(E15="MATCH",IF(D15=1,100,IF(D15=2,85,70)),0) | H15: =IF(E15="MATCH",80+MOD(ROW(),21),0) | I15: =IF(E15="MATCH",MAX(0,100-'2_Inventory_Data'!J12*0.3),0) | J15: =IF(E15="FILTERED",0,ROUND((IF('1_Inputs'!$E$5="All Ages",50,IF('1_Inputs'!$E$5="25-44",('2_Inventory_Data'!S12+'2_Inventory_Data'!T12)*100,IF('1_Inputs'!$E$5="18-24",'2_Inventory_Data'!R12*100,IF('1_Inputs'!$E$5="25-34",'2_Inventory_Data'!S12*100,IF('1_Inputs'!$E$5="35-44",'2_Inventory_Data'!T12*100,IF('1_Inputs'!$E$5="45-54",'2_Inventory_Data'!U12*100,IF('1_Inputs'!$E$5="55+",'2_Inventory_Data'!V12*100,50)))))))+IF('1_Inputs'!$E$8="All",50,IF('1_Inputs'!$E$8="Travel",'2_Inventory_Data'!AC12*100,IF('1_Inputs'!$E$8="Fashion",'2_Inventory_Data'!AD12*100,IF('1_Inputs'!$E$8="Technology",'2_Inventory_Data'!AE12*100,IF('1_Inputs'!$E$8="Food & Beverage",'2_Inventory_Data'!AF12*100,50)))))+IF('1_Inputs'!$E$9="All",50,IF('1_Inputs'!$E$9="Commuters",'2_Inventory_Data'!AG12*100,IF('1_Inputs'!$E$9="Shoppers",'2_Inventory_Data'!AH12*100,IF('1_Inputs'!$E$9="Business Travelers",'2_Inventory_Data'!AI12*100,IF('1_Inputs'!$E$9="Tourists",'2_Inventory_Data'!AJ12*100,50))))))/3,1)) | K15: =IF(E15="FILTERED",0,IF(OR('2_Inventory_Data'!I12="Transit: Airport",'2_Inventory_Data'!I12="Transit: Rail/Metro Station"),90,IF('2_Inventory_Data'!I12="Retail: Shopping Center",75,65))) | L15: =IF(E15="FILTERED",0,MIN(100,'2_Inventory_Data'!L12/5000)) | M15: =IF(E15="FILTERED",0,MIN(100,'2_Inventory_Data'!N12*4.5)) | N15: =IF(E15="FILTERED",0,ROUND(G15*0.15+H15*0.10+I15*0.18+J15*0.22+K15*0.10+L15*0.10+M15*0.10+F15*0.05,1)) | O15: =IF(N15=0,"",RANK(N15,$N$5:$N$44,0)) | P15: =IF(OR(E15="FILTERED",'2_Inventory_Data'!F12<>"Digital"),"",COUNTIFS($E$5:$E$44,"MATCH",'2_Inventory_Data'!$F$2:$F$41,"Digital",$N$5:$N$44,">"&N15)+1) | Q15: =IF(OR(E15="FILTERED",'2_Inventory_Data'!F12<>"Classic"),"",COUNTIFS($E$5:$E$44,"MATCH",'2_Inventory_Data'!$F$2:$F$41,"Classic",$N$5:$N$44,">"&N15)+1) | R15: =IF(OR(E15="FILTERED",'2_Inventory_Data'!F12<>"Audio"),"",COUNTIFS($E$5:$E$44,"MATCH",'2_Inventory_Data'!$F$2:$F$41,"Audio",$N$5:$N$44,">"&N15)+1)
A16: ='2_Inventory_Data'!A13 | B16: ='2_Inventory_Data'!B13 | C16: ='2_Inventory_Data'!D13 | D16: ='2_Inventory_Data'!E13 | E16: =IF(AND('2_Inventory_Data'!C13='1_Inputs'!$B$5,OR('1_Inputs'!$B$6="All Cities",'2_Inventory_Data'!D13='1_Inputs'!$B$6),OR('1_Inputs'!$B$14="All Venues",'2_Inventory_Data'!I13='1_Inputs'!$B$14),OR('1_Inputs'!$B$15="All",'2_Inventory_Data'!F13='1_Inputs'!$B$15),OR('1_Inputs'!$B$16="All",'2_Inventory_Data'!G13='1_Inputs'!$B$16)),"MATCH","FILTERED") | F16: =IF(E16="MATCH",100,0) | G16: =IF(E16="MATCH",IF(D16=1,100,IF(D16=2,85,70)),0) | H16: =IF(E16="MATCH",80+MOD(ROW(),21),0) | I16: =IF(E16="MATCH",MAX(0,100-'2_Inventory_Data'!J13*0.3),0) | J16: =IF(E16="FILTERED",0,ROUND((IF('1_Inputs'!$E$5="All Ages",50,IF('1_Inputs'!$E$5="25-44",('2_Inventory_Data'!S13+'2_Inventory_Data'!T13)*100,IF('1_Inputs'!$E$5="18-24",'2_Inventory_Data'!R13*100,IF('1_Inputs'!$E$5="25-34",'2_Inventory_Data'!S13*100,IF('1_Inputs'!$E$5="35-44",'2_Inventory_Data'!T13*100,IF('1_Inputs'!$E$5="45-54",'2_Inventory_Data'!U13*100,IF('1_Inputs'!$E$5="55+",'2_Inventory_Data'!V13*100,50)))))))+IF('1_Inputs'!$E$8="All",50,IF('1_Inputs'!$E$8="Travel",'2_Inventory_Data'!AC13*100,IF('1_Inputs'!$E$8="Fashion",'2_Inventory_Data'!AD13*100,IF('1_Inputs'!$E$8="Technology",'2_Inventory_Data'!AE13*100,IF('1_Inputs'!$E$8="Food & Beverage",'2_Inventory_Data'!AF13*100,50)))))+IF('1_Inputs'!$E$9="All",50,IF('1_Inputs'!$E$9="Commuters",'2_Inventory_Data'!AG13*100,IF('1_Inputs'!$E$9="Shoppers",'2_Inventory_Data'!AH13*100,IF('1_Inputs'!$E$9="Business Travelers",'2_Inventory_Data'!AI13*100,IF('1_Inputs'!$E$9="Tourists",'2_Inventory_Data'!AJ13*100,50))))))/3,1)) | K16: =IF(E16="FILTERED",0,IF(OR('2_Inventory_Data'!I13="Transit: Airport",'2_Inventory_Data'!I13="Transit: Rail/Metro Station"),90,IF('2_Inventory_Data'!I13="Retail: Shopping Center",75,65))) | L16: =IF(E16="FILTERED",0,MIN(100,'2_Inventory_Data'!L13/5000)) | M16: =IF(E16="FILTERED",0,MIN(100,'2_Inventory_Data'!N13*4.5)) | N16: =IF(E16="FILTERED",0,ROUND(G16*0.15+H16*0.10+I16*0.18+J16*0.22+K16*0.10+L16*0.10+M16*0.10+F16*0.05,1)) | O16: =IF(N16=0,"",RANK(N16,$N$5:$N$44,0)) | P16: =IF(OR(E16="FILTERED",'2_Inventory_Data'!F13<>"Digital"),"",COUNTIFS($E$5:$E$44,"MATCH",'2_Inventory_Data'!$F$2:$F$41,"Digital",$N$5:$N$44,">"&N16)+1) | Q16: =IF(OR(E16="FILTERED",'2_Inventory_Data'!F13<>"Classic"),"",COUNTIFS($E$5:$E$44,"MATCH",'2_Inventory_Data'!$F$2:$F$41,"Classic",$N$5:$N$44,">"&N16)+1) | R16: =IF(OR(E16="FILTERED",'2_Inventory_Data'!F13<>"Audio"),"",COUNTIFS($E$5:$E$44,"MATCH",'2_Inventory_Data'!$F$2:$F$41,"Audio",$N$5:$N$44,">"&N16)+1)
... A44: ='2_Inventory_Data'!A41 | B44: ='2_Inventory_Data'!B41 | C44: ='2_Inventory_Data'!D41 | D44: ='2_Inventory_Data'!E41 | E44: =IF(AND('2_Inventory_Data'!C41='1_Inputs'!$B$5,OR('1_Inputs'!$B$6="All Cities",'2_Inventory_Data'!D41='1_Inputs'!$B$6),OR('1_Inputs'!$B$14="All Venues",'2_Inventory_Data'!I41='1_Inputs'!$B$14),OR('1_Inputs'!$B$15="All",'2_Inventory_Data'!F41='1_Inputs'!$B$15),OR('1_Inputs'!$B$16="All",'2_Inventory_Data'!G41='1_Inputs'!$B$16)),"MATCH","FILTERED") | F44: =IF(E44="MATCH",100,0) | G44: =IF(E44="MATCH",IF(D44=1,100,IF(D44=2,85,70)),0) | H44: =IF(E44="MATCH",80+MOD(ROW(),21),0) | I44: =IF(E44="MATCH",MAX(0,100-'2_Inventory_Data'!J41*0.3),0) | J44: =IF(E44="FILTERED",0,ROUND((IF('1_Inputs'!$E$5="All Ages",50,IF('1_Inputs'!$E$5="25-44",('2_Inventory_Data'!S41+'2_Inventory_Data'!T41)*100,IF('1_Inputs'!$E$5="18-24",'2_Inventory_Data'!R41*100,IF('1_Inputs'!$E$5="25-34",'2_Inventory_Data'!S41*100,IF('1_Inputs'!$E$5="35-44",'2_Inventory_Data'!T41*100,IF('1_Inputs'!$E$5="45-54",'2_Inventory_Data'!U41*100,IF('1_Inputs'!$E$5="55+",'2_Inventory_Data'!V41*100,50)))))))+IF('1_Inputs'!$E$8="All",50,IF('1_Inputs'!$E$8="Travel",'2_Inventory_Data'!AC41*100,IF('1_Inputs'!$E$8="Fashion",'2_Inventory_Data'!AD41*100,IF('1_Inputs'!$E$8="Technology",'2_Inventory_Data'!AE41*100,IF('1_Inputs'!$E$8="Food & Beverage",'2_Inventory_Data'!AF41*100,50)))))+IF('1_Inputs'!$E$9="All",50,IF('1_Inputs'!$E$9="Commuters",'2_Inventory_Data'!AG41*100,IF('1_Inputs'!$E$9="Shoppers",'2_Inventory_Data'!AH41*100,IF('1_Inputs'!$E$9="Business Travelers",'2_Inventory_Data'!AI41*100,IF('1_Inputs'!$E$9="Tourists",'2_Inventory_Data'!AJ41*100,50))))))/3,1)) | K44: =IF(E44="FILTERED",0,IF(OR('2_Inventory_Data'!I41="Transit: Airport",'2_Inventory_Data'!I41="Transit: Rail/Metro Station"),90,IF('2_Inventory_Data'!I41="Retail: Shopping Center",75,65))) | L44: =IF(E44="FILTERED",0,MIN(100,'2_Inventory_Data'!L41/5000)) | M44: =IF(E44="FILTERED",0,MIN(100,'2_Inventory_Data'!N41*4.5)) | N44: =IF(E44="FILTERED",0,ROUND(G44*0.15+H44*0.10+I44*0.18+J44*0.22+K44*0.10+L44*0.10+M44*0.10+F44*0.05,1)) | O44: =IF(N44=0,"",RANK(N44,$N$5:$N$44,0)) | P44: =IF(OR(E44="FILTERED",'2_Inventory_Data'!F41<>"Digital"),"",COUNTIFS($E$5:$E$44,"MATCH",'2_Inventory_Data'!$F$2:$F$41,"Digital",$N$5:$N$44,">"&N44)+1) | Q44: =IF(OR(E44="FILTERED",'2_Inventory_Data'!F41<>"Classic"),"",COUNTIFS($E$5:$E$44,"MATCH",'2_Inventory_Data'!$F$2:$F$41,"Classic",$N$5:$N$44,">"&N44)+1) | R44: =IF(OR(E44="FILTERED",'2_Inventory_Data'!F41<>"Audio"),"",COUNTIFS($E$5:$E$44,"MATCH",'2_Inventory_Data'!$F$2:$F$41,"Audio",$N$5:$N$44,">"&N44)+1)

Sheet 4_Selection
A1: BUDGET ALLOCATION & INVENTORY SELECTION
A3: BUDGET ALLOCATION BY CLASSIFICATION
A4: Classification | B4: Allocation % | C4: Allocated Budget | D4: Inventories Matched | E4: Currency
A5: Digital | B5: ='1_Inputs'!E18 | C5: ='1_Inputs'!F18 | D5: =COUNTIFS('3_Scoring'!$E$5:$E$44,"MATCH",'2_Inventory_Data'!$F$2:$F$41,"Digital") | E5: ='1_Inputs'!C5
A6: Classic | B6: ='1_Inputs'!E19 | C6: ='1_Inputs'!F19 | D6: =COUNTIFS('3_Scoring'!$E$5:$E$44,"MATCH",'2_Inventory_Data'!$F$2:$F$41,"Classic") | E6: ='1_Inputs'!C5
A7: Audio | B7: ='1_Inputs'!E20 | C7: ='1_Inputs'!F20 | D7: =COUNTIFS('3_Scoring'!$E$5:$E$44,"MATCH",'2_Inventory_Data'!$F$2:$F$41,"Audio") | E7: ='1_Inputs'!C5
A10: DIGITAL INVENTORIES (Priority 1 - 60% Budget)
A11: Rank | B11: ID | C11: Name | D11: City | E11: Score | F11: Daily Cost | G11: Cumulative | H11: Budget Cap | I11: Selected
A12: 1 | B12: =IFERROR(INDEX('3_Scoring'!$A$5:$A$44,MATCH(1,'3_Scoring'!$P$5:$P$44,0)),"") | C12: =IF(B12="","",INDEX('3_Scoring'!$B$5:$B$44,MATCH(B12,'3_Scoring'!$A$5:$A$44,0))) | D12: =IF(B12="","",INDEX('3_Scoring'!$C$5:$C$44,MATCH(B12,'3_Scoring'!$A$5:$A$44,0))) | E12: =IF(B12="","",INDEX('3_Scoring'!$N$5:$N$44,MATCH(B12,'3_Scoring'!$A$5:$A$44,0))) | F12: =IFERROR(IF(B12="","",INDEX('2_Inventory_Data'!$L$2:$L$41,MATCH(B12,'2_Inventory_Data'!$A$2:$A$41,0))/1000*INDEX('2_Inventory_Data'!$J$2:$J$41,MATCH(B12,'2_Inventory_Data'!$A$2:$A$41,0))),"") | G12: =IF(B12="","",SUM($F$12:F12)*'1_Inputs'!$E$12) | H12: =$C$5 | I12: =IF(B12="","",IF(G12<=H12*1.05,"YES","NO"))
A13: 2 | B13: =IFERROR(INDEX('3_Scoring'!$A$5:$A$44,MATCH(2,'3_Scoring'!$P$5:$P$44,0)),"") | C13: =IF(B13="","",INDEX('3_Scoring'!$B$5:$B$44,MATCH(B13,'3_Scoring'!$A$5:$A$44,0))) | D13: =IF(B13="","",INDEX('3_Scoring'!$C$5:$C$44,MATCH(B13,'3_Scoring'!$A$5:$A$44,0))) | E13: =IF(B13="","",INDEX('3_Scoring'!$N$5:$N$44,MATCH(B13,'3_Scoring'!$A$5:$A$44,0))) | F13: =IFERROR(IF(B13="","",INDEX('2_Inventory_Data'!$L$2:$L$41,MATCH(B13,'2_Inventory_Data'!$A$2:$A$41,0))/1000*INDEX('2_Inventory_Data'!$J$2:$J$41,MATCH(B13,'2_Inventory_Data'!$A$2:$A$41,0))),"") | G13: =IF(B13="","",SUM($F$12:F13)*'1_Inputs'!$E$12) | H13: =$C$5 | I13: =IF(B13="","",IF(G13<=H13*1.05,"YES","NO"))
A14: 3 | B14: =IFERROR(INDEX('3_Scoring'!$A$5:$A$44,MATCH(3,'3_Scoring'!$P$5:$P$44,0)),"") | C14: =IF(B14="","",INDEX('3_Scoring'!$B$5:$B$44,MATCH(B14,'3_Scoring'!$A$5:$A$44,0))) | D14: =IF(B14="","",INDEX('3_Scoring'!$C$5:$C$44,MATCH(B14,'3_Scoring'!$A$5:$A$44,0))) | E14: =IF(B14="","",INDEX('3_Scoring'!$N$5:$N$44,MATCH(B14,'3_Scoring'!$A$5:$A$44,0))) | F14: =IFERROR(IF(B14="","",INDEX('2_Inventory_Data'!$L$2:$L$41,MATCH(B14,'2_Inventory_Data'!$A$2:$A$41,0))/1000*INDEX('2_Inventory_Data'!$J$2:$J$41,MATCH(B14,'2_Inventory_Data'!$A$2:$A$41,0))),"") | G14: =IF(B14="","",SUM($F$12:F14)*'1_Inputs'!$E$12) | H14: =$C$5 | I14: =IF(B14="","",IF(G14<=H14*1.05,"YES","NO"))
A15: 4 | B15: =IFERROR(INDEX('3_Scoring'!$A$5:$A$44,MATCH(4,'3_Scoring'!$P$5:$P$44,0)),"") | C15: =IF(B15="","",INDEX('3_Scoring'!$B$5:$B$44,MATCH(B15,'3_Scoring'!$A$5:$A$44,0))) | D15: =IF(B15="","",INDEX('3_Scoring'!$C$5:$C$44,MATCH(B15,'3_Scoring'!$A$5:$A$44,0))) | E15: =IF(B15="","",INDEX('3_Scoring'!$N$5:$N$44,MATCH(B15,'3_Scoring'!$A$5:$A$44,0))) | F15: =IFERROR(IF(B15="","",INDEX('2_Inventory_Data'!$L$2:$L$41,MATCH(B15,'2_Inventory_Data'!$A$2:$A$41,0))/1000*INDEX('2_Inventory_Data'!$J$2:$J$41,MATCH(B15,'2_Inventory_Data'!$A$2:$A$41,0))),"") | G15: =IF(B15="","",SUM($F$12:F15)*'1_Inputs'!$E$12) | H15: =$C$5 | I15: =IF(B15="","",IF(G15<=H15*1.05,"YES","NO"))
A16: 5 | B16: =IFERROR(INDEX('3_Scoring'!$A$5:$A$44,MATCH(5,'3_Scoring'!$P$5:$P$44,0)),"") | C16: =IF(B16="","",INDEX('3_Scoring'!$B$5:$B$44,MATCH(B16,'3_Scoring'!$A$5:$A$44,0))) | D16: =IF(B16="","",INDEX('3_Scoring'!$C$5:$C$44,MATCH(B16,'3_Scoring'!$A$5:$A$44,0))) | E16: =IF(B16="","",INDEX('3_Scoring'!$N$5:$N$44,MATCH(B16,'3_Scoring'!$A$5:$A$44,0))) | F16: =IFERROR(IF(B16="","",INDEX('2_Inventory_Data'!$L$2:$L$41,MATCH(B16,'2_Inventory_Data'!$A$2:$A$41,0))/1000*INDEX('2_Inventory_Data'!$J$2:$J$41,MATCH(B16,'2_Inventory_Data'!$A$2:$A$41,0))),"") | G16: =IF(B16="","",SUM($F$12:F16)*'1_Inputs'!$E$12) | H16: =$C$5 | I16: =IF(B16="","",IF(G16<=H16*1.05,"YES","NO"))
A17: 6 | B17: =IFERROR(INDEX('3_Scoring'!$A$5:$A$44,MATCH(6,'3_Scoring'!$P$5:$P$44,0)),"") | C17: =IF(B17="","",INDEX('3_Scoring'!$B$5:$B$44,MATCH(B17,'3_Scoring'!$A$5:$A$44,0))) | D17: =IF(B17="","",INDEX('3_Scoring'!$C$5:$C$44,MATCH(B17,'3_Scoring'!$A$5:$A$44,0))) | E17: =IF(B17="","",INDEX('3_Scoring'!$N$5:$N$44,MATCH(B17,'3_Scoring'!$A$5:$A$44,0))) | F17: =IFERROR(IF(B17="","",INDEX('2_Inventory_Data'!$L$2:$L$41,MATCH(B17,'2_Inventory_Data'!$A$2:$A$41,0))/1000*INDEX('2_Inventory_Data'!$J$2:$J$41,MATCH(B17,'2_Inventory_Data'!$A$2:$A$41,0))),"") | G17: =IF(B17="","",SUM($F$12:F17)*'1_Inputs'!$E$12) | H17: =$C$5 | I17: =IF(B17="","",IF(G17<=H17*1.05,"YES","NO"))
A19: CLASSIC INVENTORIES (Priority 2 - 35% Budget)
A20: Rank | B20: ID | C20: Name | D20: City | E20: Score | F20: Daily Cost | G20: Cumulative | H20: Budget Cap | I20: Selected
A21: 1 | B21: =IFERROR(INDEX('3_Scoring'!$A$5:$A$44,MATCH(1,'3_Scoring'!$Q$5:$Q$44,0)),"") | C21: =IF(B21="","",INDEX('3_Scoring'!$B$5:$B$44,MATCH(B21,'3_Scoring'!$A$5:$A$44,0))) | D21: =IF(B21="","",INDEX('3_Scoring'!$C$5:$C$44,MATCH(B21,'3_Scoring'!$A$5:$A$44,0))) | E21: =IF(B21="","",INDEX('3_Scoring'!$N$5:$N$44,MATCH(B21,'3_Scoring'!$A$5:$A$44,0))) | F21: =IFERROR(IF(B21="","",INDEX('2_Inventory_Data'!$L$2:$L$41,MATCH(B21,'2_Inventory_Data'!$A$2:$A$41,0))/1000*INDEX('2_Inventory_Data'!$J$2:$J$41,MATCH(B21,'2_Inventory_Data'!$A$2:$A$41,0))),"") | G21: =IF(B21="","",SUM($F$21:F21)*'1_Inputs'!$E$12) | H21: =$C$6 | I21: =IF(B21="","",IF(G21<=H21*1.05,"YES","NO"))
A22: 2 | B22: =IFERROR(INDEX('3_Scoring'!$A$5:$A$44,MATCH(2,'3_Scoring'!$Q$5:$Q$44,0)),"") | C22: =IF(B22="","",INDEX('3_Scoring'!$B$5:$B$44,MATCH(B22,'3_Scoring'!$A$5:$A$44,0))) | D22: =IF(B22="","",INDEX('3_Scoring'!$C$5:$C$44,MATCH(B22,'3_Scoring'!$A$5:$A$44,0))) | E22: =IF(B22="","",INDEX('3_Scoring'!$N$5:$N$44,MATCH(B22,'3_Scoring'!$A$5:$A$44,0))) | F22: =IFERROR(IF(B22="","",INDEX('2_Inventory_Data'!$L$2:$L$41,MATCH(B22,'2_Inventory_Data'!$A$2:$A$41,0))/1000*INDEX('2_Inventory_Data'!$J$2:$J$41,MATCH(B22,'2_Inventory_Data'!$A$2:$A$41,0))),"") | G22: =IF(B22="","",SUM($F$21:F22)*'1_Inputs'!$E$12) | H22: =$C$6 | I22: =IF(B22="","",IF(G22<=H22*1.05,"YES","NO"))
A23: 3 | B23: =IFERROR(INDEX('3_Scoring'!$A$5:$A$44,MATCH(3,'3_Scoring'!$Q$5:$Q$44,0)),"") | C23: =IF(B23="","",INDEX('3_Scoring'!$B$5:$B$44,MATCH(B23,'3_Scoring'!$A$5:$A$44,0))) | D23: =IF(B23="","",INDEX('3_Scoring'!$C$5:$C$44,MATCH(B23,'3_Scoring'!$A$5:$A$44,0))) | E23: =IF(B23="","",INDEX('3_Scoring'!$N$5:$N$44,MATCH(B23,'3_Scoring'!$A$5:$A$44,0))) | F23: =IFERROR(IF(B23="","",INDEX('2_Inventory_Data'!$L$2:$L$41,MATCH(B23,'2_Inventory_Data'!$A$2:$A$41,0))/1000*INDEX('2_Inventory_Data'!$J$2:$J$41,MATCH(B23,'2_Inventory_Data'!$A$2:$A$41,0))),"") | G23: =IF(B23="","",SUM($F$21:F23)*'1_Inputs'!$E$12) | H23: =$C$6 | I23: =IF(B23="","",IF(G23<=H23*1.05,"YES","NO"))
A24: 4 | B24: =IFERROR(INDEX('3_Scoring'!$A$5:$A$44,MATCH(4,'3_Scoring'!$Q$5:$Q$44,0)),"") | C24: =IF(B24="","",INDEX('3_Scoring'!$B$5:$B$44,MATCH(B24,'3_Scoring'!$A$5:$A$44,0))) | D24: =IF(B24="","",INDEX('3_Scoring'!$C$5:$C$44,MATCH(B24,'3_Scoring'!$A$5:$A$44,0))) | E24: =IF(B24="","",INDEX('3_Scoring'!$N$5:$N$44,MATCH(B24,'3_Scoring'!$A$5:$A$44,0))) | F24: =IFERROR(IF(B24="","",INDEX('2_Inventory_Data'!$L$2:$L$41,MATCH(B24,'2_Inventory_Data'!$A$2:$A$41,0))/1000*INDEX('2_Inventory_Data'!$J$2:$J$41,MATCH(B24,'2_Inventory_Data'!$A$2:$A$41,0))),"") | G24: =IF(B24="","",SUM($F$21:F24)*'1_Inputs'!$E$12) | H24: =$C$6 | I24: =IF(B24="","",IF(G24<=H24*1.05,"YES","NO"))
A25: 5 | B25: =IFERROR(INDEX('3_Scoring'!$A$5:$A$44,MATCH(5,'3_Scoring'!$Q$5:$Q$44,0)),"") | C25: =IF(B25="","",INDEX('3_Scoring'!$B$5:$B$44,MATCH(B25,'3_Scoring'!$A$5:$A$44,0))) | D25: =IF(B25="","",INDEX('3_Scoring'!$C$5:$C$44,MATCH(B25,'3_Scoring'!$A$5:$A$44,0))) | E25: =IF(B25="","",INDEX('3_Scoring'!$N$5:$N$44,MATCH(B25,'3_Scoring'!$A$5:$A$44,0))) | F25: =IFERROR(IF(B25="","",INDEX('2_Inventory_Data'!$L$2:$L$41,MATCH(B25,'2_Inventory_Data'!$A$2:$A$41,0))/1000*INDEX('2_Inventory_Data'!$J$2:$J$41,MATCH(B25,'2_Inventory_Data'!$A$2:$A$41,0))),"") | G25: =IF(B25="","",SUM($F$21:F25)*'1_Inputs'!$E$12) | H25: =$C$6 | I25: =IF(B25="","",IF(G25<=H25*1.05,"YES","NO"))
A27: AUDIO INVENTORIES (Priority 3 - 5% Budget, Lowest Priority)
A28: Rank | B28: ID | C28: Name | D28: City | E28: Score | F28: Daily Cost | G28: Cumulative | H28: Budget Cap | I28: Selected
A29: 1 | B29: =IFERROR(INDEX('3_Scoring'!$A$5:$A$44,MATCH(1,'3_Scoring'!$R$5:$R$44,0)),"") | C29: =IF(B29="","",INDEX('3_Scoring'!$B$5:$B$44,MATCH(B29,'3_Scoring'!$A$5:$A$44,0))) | D29: =IF(B29="","",INDEX('3_Scoring'!$C$5:$C$44,MATCH(B29,'3_Scoring'!$A$5:$A$44,0))) | E29: =IF(B29="","",INDEX('3_Scoring'!$N$5:$N$44,MATCH(B29,'3_Scoring'!$A$5:$A$44,0))) | F29: =IFERROR(IF(B29="","",INDEX('2_Inventory_Data'!$L$2:$L$41,MATCH(B29,'2_Inventory_Data'!$A$2:$A$41,0))/1000*INDEX('2_Inventory_Data'!$J$2:$J$41,MATCH(B29,'2_Inventory_Data'!$A$2:$A$41,0))),"") | G29: =IF(B29="","",SUM($F$29:F29)*'1_Inputs'!$E$12) | H29: =$C$7 | I29: =IF(B29="","",IF(AND(G29<=H29*1.05,$B$7>0),"YES","NO"))
A30: 2 | B30: =IFERROR(INDEX('3_Scoring'!$A$5:$A$44,MATCH(2,'3_Scoring'!$R$5:$R$44,0)),"") | C30: =IF(B30="","",INDEX('3_Scoring'!$B$5:$B$44,MATCH(B30,'3_Scoring'!$A$5:$A$44,0))) | D30: =IF(B30="","",INDEX('3_Scoring'!$C$5:$C$44,MATCH(B30,'3_Scoring'!$A$5:$A$44,0))) | E30: =IF(B30="","",INDEX('3_Scoring'!$N$5:$N$44,MATCH(B30,'3_Scoring'!$A$5:$A$44,0))) | F30: =IFERROR(IF(B30="","",INDEX('2_Inventory_Data'!$L$2:$L$41,MATCH(B30,'2_Inventory_Data'!$A$2:$A$41,0))/1000*INDEX('2_Inventory_Data'!$J$2:$J$41,MATCH(B30,'2_Inventory_Data'!$A$2:$A$41,0))),"") | G30: =IF(B30="","",SUM($F$29:F30)*'1_Inputs'!$E$12) | H30: =$C$7 | I30: =IF(B30="","",IF(AND(G30<=H30*1.05,$B$7>0),"YES","NO"))
A31: 3 | B31: =IFERROR(INDEX('3_Scoring'!$A$5:$A$44,MATCH(3,'3_Scoring'!$R$5:$R$44,0)),"") | C31: =IF(B31="","",INDEX('3_Scoring'!$B$5:$B$44,MATCH(B31,'3_Scoring'!$A$5:$A$44,0))) | D31: =IF(B31="","",INDEX('3_Scoring'!$C$5:$C$44,MATCH(B31,'3_Scoring'!$A$5:$A$44,0))) | E31: =IF(B31="","",INDEX('3_Scoring'!$N$5:$N$44,MATCH(B31,'3_Scoring'!$A$5:$A$44,0))) | F31: =IFERROR(IF(B31="","",INDEX('2_Inventory_Data'!$L$2:$L$41,MATCH(B31,'2_Inventory_Data'!$A$2:$A$41,0))/1000*INDEX('2_Inventory_Data'!$J$2:$J$41,MATCH(B31,'2_Inventory_Data'!$A$2:$A$41,0))),"") | G31: =IF(B31="","",SUM($F$29:F31)*'1_Inputs'!$E$12) | H31: =$C$7 | I31: =IF(B31="","",IF(AND(G31<=H31*1.05,$B$7>0),"YES","NO"))
A32: Note: Audio is lowest priority. Only selected when allocation > 0% and within budget cap.

Sheet 5_Schedules
A1: SCHEDULE CREATION - DETAILED VIEW
A2: Each selected inventory gets a schedule with start/end dates and optimal time slots based on operating hours.
A4: Inventory ID | B4: Name | C4: City | D4: Classification | E4: Start Date | F4: Start Time | G4: End Date | H4: End Time | I4: Op. Hours | J4: Hours/Day | K4: Daily Impr. | L4: Daily Cost | M4: Campaign Impr. | N4: Campaign Cost | O4: Contrib. to Goal
A5: =IF('4_Selection'!I12="YES",'4_Selection'!B12,"") | B5: =IF(A5="","",'4_Selection'!C12) | C5: =IF(A5="","",'4_Selection'!D12) | D5: =IF(A5="","",INDEX('2_Inventory_Data'!$F$2:$F$41,MATCH(A5,'2_Inventory_Data'!$A$2:$A$41,0))) | E5: =IF(A5="","",'1_Inputs'!$B$7) | F5: =IF(A5="","",IF(INDEX('2_Inventory_Data'!$N$2:$N$41,MATCH(A5,'2_Inventory_Data'!$A$2:$A$41,0))>=20,"06:00",IF(INDEX('2_Inventory_Data'!$N$2:$N$41,MATCH(A5,'2_Inventory_Data'!$A$2:$A$41,0))>=16,"07:00","08:00"))) | G5: =IF(A5="","",'1_Inputs'!$B$8) | H5: =IF(A5="","",IF(INDEX('2_Inventory_Data'!$N$2:$N$41,MATCH(A5,'2_Inventory_Data'!$A$2:$A$41,0))=24,"23:59",TEXT(MIN(23,VALUE(LEFT(F5,2))+MIN(12,INDEX('2_Inventory_Data'!$N$2:$N$41,MATCH(A5,'2_Inventory_Data'!$A$2:$A$41,0)))),"00")&":00")) | I5: =IF(A5="","",INDEX('2_Inventory_Data'!$N$2:$N$41,MATCH(A5,'2_Inventory_Data'!$A$2:$A$41,0))) | J5: =IF(A5="","",MIN(I5,12)) | K5: =IF(A5="","",ROUND(INDEX('2_Inventory_Data'!$L$2:$L$41,MATCH(A5,'2_Inventory_Data'!$A$2:$A$41,0))*(J5/I5),0)) | L5: =IF(A5="","",'4_Selection'!G12) | M5: =IF(A5="","",K5*'1_Inputs'!$E$12) | N5: =IF(A5="","",L5*'1_Inputs'!$E$12) | O5: =IF(A5="","",IFERROR(M5/'1_Inputs'!$B$11,0))
A6: =IF('4_Selection'!I13="YES",'4_Selection'!B13,"") | B6: =IF(A6="","",'4_Selection'!C13) | C6: =IF(A6="","",'4_Selection'!D13) | D6: =IF(A6="","",INDEX('2_Inventory_Data'!$F$2:$F$41,MATCH(A6,'2_Inventory_Data'!$A$2:$A$41,0))) | E6: =IF(A6="","",'1_Inputs'!$B$7) | F6: =IF(A6="","",IF(INDEX('2_Inventory_Data'!$N$2:$N$41,MATCH(A6,'2_Inventory_Data'!$A$2:$A$41,0))>=20,"06:00",IF(INDEX('2_Inventory_Data'!$N$2:$N$41,MATCH(A6,'2_Inventory_Data'!$A$2:$A$41,0))>=16,"07:00","08:00"))) | G6: =IF(A6="","",'1_Inputs'!$B$8) | H6: =IF(A6="","",IF(INDEX('2_Inventory_Data'!$N$2:$N$41,MATCH(A6,'2_Inventory_Data'!$A$2:$A$41,0))=24,"23:59",TEXT(MIN(23,VALUE(LEFT(F6,2))+MIN(12,INDEX('2_Inventory_Data'!$N$2:$N$41,MATCH(A6,'2_Inventory_Data'!$A$2:$A$41,0)))),"00")&":00")) | I6: =IF(A6="","",INDEX('2_Inventory_Data'!$N$2:$N$41,MATCH(A6,'2_Inventory_Data'!$A$2:$A$41,0))) | J6: =IF(A6="","",MIN(I6,12)) | K6: =IF(A6="","",ROUND(INDEX('2_Inventory_Data'!$L$2:$L$41,MATCH(A6,'2_Inventory_Data'!$A$2:$A$41,0))*(J6/I6),0)) | L6: =IF(A6="","",'4_Selection'!G13) | M6: =IF(A6="","",K6*'1_Inputs'!$E$12) | N6: =IF(A6="","",L6*'1_Inputs'!$E$12) | O6: =IF(A6="","",IFERROR(M6/'1_Inputs'!$B$11,0))
A7: =IF('4_Selection'!I14="YES",'4_Selection'!B14,"") | B7: =IF(A7="","",'4_Selection'!C14) | C7: =IF(A7="","",'4_Selection'!D14) | D7: =IF(A7="","",INDEX('2_Inventory_Data'!$F$2:$F$41,MATCH(A7,'2_Inventory_Data'!$A$2:$A$41,0))) | E7: =IF(A7="","",'1_Inputs'!$B$7) | F7: =IF(A7="","",IF(INDEX('2_Inventory_Data'!$N$2:$N$41,MATCH(A7,'2_Inventory_Data'!$A$2:$A$41,0))>=20,"06:00",IF(INDEX('2_Inventory_Data'!$N$2:$N$41,MATCH(A7,'2_Inventory_Data'!$A$2:$A$41,0))>=16,"07:00","08:00"))) | G7: =IF(A7="","",'1_Inputs'!$B$8) | H7: =IF(A7="","",IF(INDEX('2_Inventory_Data'!$N$2:$N$41,MATCH(A7,'2_Inventory_Data'!$A$2:$A$41,0))=24,"23:59",TEXT(MIN(23,VALUE(LEFT(F7,2))+MIN(12,INDEX('2_Inventory_Data'!$N$2:$N$41,MATCH(A7,'2_Inventory_Data'!$A$2:$A$41,0)))),"00")&":00")) | I7: =IF(A7="","",INDEX('2_Inventory_Data'!$N$2:$N$41,MATCH(A7,'2_Inventory_Data'!$A$2:$A$41,0))) | J7: =IF(A7="","",MIN(I7,12)) | K7: =IF(A7="","",ROUND(INDEX('2_Inventory_Data'!$L$2:$L$41,MATCH(A7,'2_Inventory_Data'!$A$2:$A$41,0))*(J7/I7),0)) | L7: =IF(A7="","",'4_Selection'!G14) | M7: =IF(A7="","",K7*'1_Inputs'!$E$12) | N7: =IF(A7="","",L7*'1_Inputs'!$E$12) | O7: =IF(A7="","",IFERROR(M7/'1_Inputs'!$B$11,0))
A8: =IF('4_Selection'!I15="YES",'4_Selection'!B15,"") | B8: =IF(A8="","",'4_Selection'!C15) | C8: =IF(A8="","",'4_Selection'!D15) | D8: =IF(A8="","",INDEX('2_Inventory_Data'!$F$2:$F$41,MATCH(A8,'2_Inventory_Data'!$A$2:$A$41,0))) | E8: =IF(A8="","",'1_Inputs'!$B$7) | F8: =IF(A8="","",IF(INDEX('2_Inventory_Data'!$N$2:$N$41,MATCH(A8,'2_Inventory_Data'!$A$2:$A$41,0))>=20,"06:00",IF(INDEX('2_Inventory_Data'!$N$2:$N$41,MATCH(A8,'2_Inventory_Data'!$A$2:$A$41,0))>=16,"07:00","08:00"))) | G8: =IF(A8="","",'1_Inputs'!$B$8) | H8: =IF(A8="","",IF(INDEX('2_Inventory_Data'!$N$2:$N$41,MATCH(A8,'2_Inventory_Data'!$A$2:$A$41,0))=24,"23:59",TEXT(MIN(23,VALUE(LEFT(F8,2))+MIN(12,INDEX('2_Inventory_Data'!$N$2:$N$41,MATCH(A8,'2_Inventory_Data'!$A$2:$A$41,0)))),"00")&":00")) | I8: =IF(A8="","",INDEX('2_Inventory_Data'!$N$2:$N$41,MATCH(A8,'2_Inventory_Data'!$A$2:$A$41,0))) | J8: =IF(A8="","",MIN(I8,12)) | K8: =IF(A8="","",ROUND(INDEX('2_Inventory_Data'!$L$2:$L$41,MATCH(A8,'2_Inventory_Data'!$A$2:$A$41,0))*(J8/I8),0)) | L8: =IF(A8="","",'4_Selection'!G15) | M8: =IF(A8="","",K8*'1_Inputs'!$E$12) | N8: =IF(A8="","",L8*'1_Inputs'!$E$12) | O8: =IF(A8="","",IFERROR(M8/'1_Inputs'!$B$11,0))
A9: =IF('4_Selection'!I16="YES",'4_Selection'!B16,"") | B9: =IF(A9="","",'4_Selection'!C16) | C9: =IF(A9="","",'4_Selection'!D16) | D9: =IF(A9="","",INDEX('2_Inventory_Data'!$F$2:$F$41,MATCH(A9,'2_Inventory_Data'!$A$2:$A$41,0))) | E9: =IF(A9="","",'1_Inputs'!$B$7) | F9: =IF(A9="","",IF(INDEX('2_Inventory_Data'!$N$2:$N$41,MATCH(A9,'2_Inventory_Data'!$A$2:$A$41,0))>=20,"06:00",IF(INDEX('2_Inventory_Data'!$N$2:$N$41,MATCH(A9,'2_Inventory_Data'!$A$2:$A$41,0))>=16,"07:00","08:00"))) | G9: =IF(A9="","",'1_Inputs'!$B$8) | H9: =IF(A9="","",IF(INDEX('2_Inventory_Data'!$N$2:$N$41,MATCH(A9,'2_Inventory_Data'!$A$2:$A$41,0))=24,"23:59",TEXT(MIN(23,VALUE(LEFT(F9,2))+MIN(12,INDEX('2_Inventory_Data'!$N$2:$N$41,MATCH(A9,'2_Inventory_Data'!$A$2:$A$41,0)))),"00")&":00")) | I9: =IF(A9="","",INDEX('2_Inventory_Data'!$N$2:$N$41,MATCH(A9,'2_Inventory_Data'!$A$2:$A$41,0))) | J9: =IF(A9="","",MIN(I9,12)) | K9: =IF(A9="","",ROUND(INDEX('2_Inventory_Data'!$L$2:$L$41,MATCH(A9,'2_Inventory_Data'!$A$2:$A$41,0))*(J9/I9),0)) | L9: =IF(A9="","",'4_Selection'!G16) | M9: =IF(A9="","",K9*'1_Inputs'!$E$12) | N9: =IF(A9="","",L9*'1_Inputs'!$E$12) | O9: =IF(A9="","",IFERROR(M9/'1_Inputs'!$B$11,0))
